INFO: > cmd='/venv/bin/invoke pytest_repro --file-name=/app/helpers/test/outcomes/Test_pytest_repro_end_to_end.test5/input/log.txt --show-stacktrace'
## pytest_repro: 
HH:MM:SS - INFO  lib_tasks.py pytest_repro:{LINE_NUM}                         Reading file_name='/app/helpers/test/outcomes/Test_pytest_repro_end_to_end.test5/input/log.txt'
HH:MM:SS - INFO  lib_tasks.py pytest_repro:{LINE_NUM}                         Reading failed tests from file '/app/helpers/test/outcomes/Test_pytest_repro_end_to_end.test5/input/log.txt'
HH:MM:SS - INFO  lib_tasks.py pytest_repro:{LINE_NUM}                         Found 1 failed pytest 'tests' target(s); to reproduce run:
pytest dataflow/pipelines/E8/test/test_E8a_pipeline.py::TestE8a_ModelBuilder::test1

# TestE8a_ModelBuilder.test1
Traceback (most recent call last):
  File "/app/dataflow/pipelines/E8/test/test_E8a_pipeline.py", line 72, in test1
    self.check_string(actual)
  File "/app/helpers/hunit_test.py", line 1360, in check_string
    hdbg.dfatal(msg)
  File "/app/helpers/hdbg.py", line 63, in dfatal
    raise assertion_type(ret)
AssertionError:
################################################################################
The golden outcome doesn't exist: saved the actual output in '/app/dataflow/pipelines/E8/test/TestE8a_ModelBuilder.test1/output/test.txt.tmp'
################################################################################


# To run the tests:
> ./tmp.pytest_repro.sh